/*
   When we use the throw keyword, the error is thrown and code after throw statement will not execute.

   Following the try block is the catch statement which accepts the thrown error from the try block. The e represents the thrown error.
   The curly braces that follow catch(e) is known as the catch block and contains code that executes to handle the error.
*/

try {
  throw Error("wrong input");
} catch (e) { 
  console.log(e);
}

Output:
Error: wrong input
    at Object.<anonymous> (/home/ccuser/workspace/error-handling-try-catch-i/main.js:2:9)
    at Module._compile (module.js:571:32)
    at Object.Module._extensions..js (module.js:580:10)
    at Module.load (module.js:488:32)
    at tryModuleLoad (module.js:447:12)
    at Function.Module._load (module.js:439:3)
    at Module.runMain (module.js:605:10)
    at run (bootstrap_node.js:427:7)
    at startup (bootstrap_node.js:151:9)
    at bootstrap_node.js:542:3